Workbook

Sheet 账单总览
B1: 客户月结总览
B5: 客户名称: | D5: 深圳市嘉嘉电科技有限公司 | H5: 顺丰对账人: | J5: 丰晓易
B6: 月结卡号: | D6: 7551083218 | H6: 对账热线: | J6: 4001095338
B7: 账单周期: | D7: 20251201-20251231 | H7: 联系邮箱: | J7: sfcscs@sf-express.com
B8: 最晚汇款日: | D8: 2026-01-31 | H8: 服务时间: | J8: 工作日周一至周五9:00-17:30
B11: 本期应付总额: | E11: ¥4,210.50
B12: 本期应付金额： | E12: ¥4,210.50
B13: 月结券抵扣: | E13: ¥0.00
B16: 费用类型 | D16: 费用 | G16: 折扣/促销 | J16: 应付金额
B17: 速运费用 | D17: 4210.5 | G17: 0 | J17: 4210.5
B18: 小计 | D18: 4210.5 | G18: 0 | J18: 4210.5
B21: 对公账户信息
B22: 速运公司
B23: 公司名称: | C23: 顺丰速运有限公司
B24: 银行名称: | C24: 中国工商银行股份有限公司前海分行
B25: 银行账号: | C25: 4000025319200395130
B28: 客户经理联系信息
B29: 联系人: | C29: 李先亮 | H29: 联系电话: | I29: 18823870296
B31: 温馨提示：
B32: ◆若您的账单地址、电邮地址等联系方式发生变化，为确保您能准确无误的收到账单，您可访问微信公众号“顺丰速运
B33: 月结服务”，及时更新您的信息。
B34: ◆您可通过银行转账、微信、支付宝等方式直接支付到我司账户，请勿将资金以现金或其他方式交付给我司员工个人账
B35: 户。如因支付给我司员工个人 账户造成的纠纷，我司不承担相关责任。
B36: ◆若您使用了我司国际件免税（增值税）产品服务需开具发票，请特别注意该服务发票开具主体为广东顺丰电子商务有
B37: 限公司，发票类型为普通发票；但您的款项请支付至上方所列公司及账号。
B38: ◆免税产品：顺丰国际电商专递、顺丰国际小包挂号、顺丰国际小包平邮、国际海运、国际重货-港到港、国际铁路整
B39: 柜、国际铁路散货、国际重货-陆运、国际重货-海外仓空+派、国际重货-海外仓海+派、国际重货-海外仓铁+派、国际仓
B40: 储、国际填舱。
B41: ◆我司自2019年4月开始向中国内地始发的国际标快+、国际标快、国际特惠产品收取燃油附加费， https://www.sf-express
B42: .com/chn/sc/support-more/international_fuel_surcharge_introduction查看当月燃油费率及计算方法。
... B45: ◆若贵司需变更开票信息或对账单内容有疑问，请联系顺丰对账联系人。

Sheet 账单明细
A1: 快递运单费用
A2: 序号 | B2: 日期 | C2: 运单号码 | D2: 寄件地区 | E2: 到件地区 | F2: 对方公司名称 | G2: 计费重量 | H2: 产品类型 | I2: 付款方式 | J2: 费用(元) | K2: 折扣/促销 | L2: 应付金额 | M2: 经手人 | N2: 服务 | O2: 任务类型 | P2: 下单账号 | Q2: 账号所属公司 | R2: 公司性质 | S2: 备注
A3: 1 | B3: 12-01 | C3: SF3262372117661 | D3: 雅安 | E3: 成都/资阳/眉山 | F3: 文刚 | G3: 1.000 | H3: 顺丰标快 | I3: 寄转第三方 | J3: 13.00 | K3: 0.00 | L3: 13.00 | M3: 文刚 | N3: 运费 | O3: =VLOOKUP(C3,Sheet2!A:C,2,FALSE) -> 取宝-物流服务 | P3: =VLOOKUP(C3,Sheet2!G:H,2,FALSE) -> 134****6101 | Q3: 成都江源易通信息技术有限公司
A4: 2 | B4: 12-01 | C4: SF3262372117661 | D4: 雅安 | E4: 成都/资阳/眉山 | F4: 文刚 | G4: 0.000 | H4: 顺丰标快 | I4: 寄转第三方 | J4: 2.00 | K4: 0.00 | L4: 2.00 | M4: 文刚 | N4: 包装服务 | O4: =VLOOKUP(C4,Sheet2!A:C,2,FALSE) -> 取宝-物流服务 | P4: =VLOOKUP(C4,Sheet2!G:H,2,FALSE) -> 134****6101 | Q4: 成都江源易通信息技术有限公司
A5: 3 | B5: 12-01 | C5: SF3262372954357 | D5: 雅安 | E5: 成都/资阳/眉山 | F5: 文刚 | G5: 4.500 | H5: 顺丰标快 | I5: 寄转第三方 | J5: 20.00 | K5: 0.00 | L5: 20.00 | M5: 文刚 | N5: 运费 | O5: =VLOOKUP(C5,Sheet2!A:C,2,FALSE) -> 立充充电宝取机柜-物流服务 | P5: =VLOOKUP(C5,Sheet2!G:H,2,FALSE) -> 134****6101 | Q5: 成都江源易通信息技术有限公司
A6: 4 | B6: 12-01 | C6: SF3262372954357 | D6: 雅安 | E6: 成都/资阳/眉山 | F6: 文刚 | G6: 0.000 | H6: 顺丰标快 | I6: 寄转第三方 | J6: 7.00 | K6: 0.00 | L6: 7.00 | M6: 文刚 | N6: 包装服务 | O6: =VLOOKUP(C6,Sheet2!A:C,2,FALSE) -> 立充充电宝取机柜-物流服务 | P6: =VLOOKUP(C6,Sheet2!G:H,2,FALSE) -> 134****6101 | Q6: 成都江源易通信息技术有限公司
A7: 5 | B7: 12-01 | C7: SF3262377404072 | D7: 东莞 | E7: 东莞 | F7: 邹小华 | G7: 1.000 | H7: 顺丰标快 | I7: 寄转第三方 | J7: 11.00 | K7: 0.00 | L7: 11.00 | M7: 邹小华 | N7: 运费 | O7: =VLOOKUP(C7,Sheet2!A:C,2,FALSE) -> 取宝-物流服务 | P7: =VLOOKUP(C7,Sheet2!G:H,2,FALSE) -> 186****6788 | Q7: 东莞市中汇信息技术有限公司
A8: 6 | B8: 12-01 | C8: SF3262377404072 | D8: 东莞 | E8: 东莞 | F8: 邹小华 | G8: 0.000 | H8: 顺丰标快 | I8: 寄转第三方 | J8: 2.00 | K8: 0.00 | L8: 2.00 | M8: 邹小华 | N8: 包装服务 | O8: =VLOOKUP(C8,Sheet2!A:C,2,FALSE) -> 取宝-物流服务 | P8: =VLOOKUP(C8,Sheet2!G:H,2,FALSE) -> 186****6788 | Q8: 东莞市中汇信息技术有限公司
A9: 7 | B9: 12-01 | C9: SF3262378607753 | D9: 东莞 | E9: 东莞 | F9: 邹小华 | G9: 1.000 | H9: 顺丰标快 | I9: 寄转第三方 | J9: 11.00 | K9: 0.00 | L9: 11.00 | M9: 邹小华 | N9: 运费 | O9: =VLOOKUP(C9,Sheet2!A:C,2,FALSE) -> 取宝-物流服务 | P9: =VLOOKUP(C9,Sheet2!G:H,2,FALSE) -> 186****6788 | Q9: 东莞市中汇信息技术有限公司
A10: 8 | B10: 12-01 | C10: SF3295326848005 | D10: 东莞 | E10: 东莞 | F10: 邹小华 | G10: 1.000 | H10: 顺丰标快 | I10: 寄转第三方 | J10: 11.00 | K10: 0.00 | L10: 11.00 | M10: 邹小华 | N10: 运费 | O10: =VLOOKUP(C10,Sheet2!A:C,2,FALSE) -> 取宝-物流服务 | P10: =VLOOKUP(C10,Sheet2!G:H,2,FALSE) -> 186****6788 | Q10: 东莞市中汇信息技术有限公司
A11: 9 | B11: 12-01 | C11: SF3295326848005 | D11: 东莞 | E11: 东莞 | F11: 邹小华 | G11: 0.000 | H11: 顺丰标快 | I11: 寄转第三方 | J11: 1.00 | K11: 0.00 | L11: 1.00 | M11: 邹小华 | N11: 包装服务 | O11: =VLOOKUP(C11,Sheet2!A:C,2,FALSE) -> 取宝-物流服务 | P11: =VLOOKUP(C11,Sheet2!G:H,2,FALSE) -> 186****6788 | Q11: 东莞市中汇信息技术有限公司
A12: 10 | B12: 12-01 | C12: SF3295364078732 | D12: 雅安 | E12: 成都/资阳/眉山 | F12: 文刚 | G12: 1.000 | H12: 顺丰标快 | I12: 寄转第三方 | J12: 13.00 | K12: 0.00 | L12: 13.00 | M12: 文刚 | N12: 运费 | O12: =VLOOKUP(C12,Sheet2!A:C,2,FALSE) -> 取宝-物流服务 | P12: =VLOOKUP(C12,Sheet2!G:H,2,FALSE) -> 134****6101 | Q12: 成都江源易通信息技术有限公司
A13: 11 | B13: 12-01 | C13: SF3295364078732 | D13: 雅安 | E13: 成都/资阳/眉山 | F13: 文刚 | G13: 0.000 | H13: 顺丰标快 | I13: 寄转第三方 | J13: 2.00 | K13: 0.00 | L13: 2.00 | M13: 文刚 | N13: 包装服务 | O13: =VLOOKUP(C13,Sheet2!A:C,2,FALSE) -> 取宝-物流服务 | P13: =VLOOKUP(C13,Sheet2!G:H,2,FALSE) -> 134****6101 | Q13: 成都江源易通信息技术有限公司
A14: 12 | B14: 12-01 | C14: SF3295364078769 | D14: 雅安 | E14: 成都/资阳/眉山 | F14: 文刚 | G14: 1.000 | H14: 顺丰标快 | I14: 寄转第三方 | J14: 13.00 | K14: 0.00 | L14: 13.00 | M14: 文刚 | N14: 运费 | O14: =VLOOKUP(C14,Sheet2!A:C,2,FALSE) -> 取宝-物流服务 | P14: =VLOOKUP(C14,Sheet2!G:H,2,FALSE) -> 134****6101 | Q14: 成都江源易通信息技术有限公司
... A20: 18 | B20: 12-02 | C20: SF3262378607753 | D20: 东莞 | E20: 东莞 | F20: 邹小华 | G20: 0.000 | H20: 顺丰标快 | I20: 寄付 | J20: 6.00 | K20: 0.00 | L20: 6.00 | M20: 邹小华 | N20: 收件微派 | O20: =VLOOKUP(C20,Sheet2!A:C,2,FALSE) -> 取宝-物流服务 | P20: =VLOOKUP(C20,Sheet2!G:H,2,FALSE) -> 186****6788 | Q20: 东莞市中汇信息技术有限公司
A21: 19 | B21: 12-02 | C21: SF3262992584639 | D21: 深圳 | E21: 东莞 | F21: 广东久益智付科技有限公司 | G21: 1.000 | H21: 顺丰标快 | I21: 寄转第三方 | J21: 13.00 | K21: 0.00 | L21: 13.00 | M21: 吴广继 | N21: 运费 | O21: =VLOOKUP(C21,Sheet2!A:C,2,FALSE) -> 取宝-仅物流 | P21: 130****4667‎‎‎‬‬‬ | Q21: 广东久益智付科技有限公司
A22: 20 | B22: 12-02 | C22: SF3295326848005 | D22: 东莞 | E22: 东莞 | F22: 邹小华 | G22: 0.000 | H22: 顺丰标快 | I22: 寄付 | J22: 6.00 | K22: 0.00 | L22: 6.00 | M22: 邹小华 | N22: 收件微派 | O22: =VLOOKUP(C22,Sheet2!A:C,2,FALSE) -> 取宝-物流服务 | P22: =VLOOKUP(C22,Sheet2!G:H,2,FALSE) -> 186****6788 | Q22: 东莞市中汇信息技术有限公司
A23: 21 | B23: 12-02 | C23: SF3295364078732 | D23: 雅安 | E23: 成都/资阳/眉山 | F23: 文刚 | G23: 0.000 | H23: 顺丰标快 | I23: 寄付 | J23: 6.00 | K23: 0.00 | L23: 6.00 | M23: 文刚 | N23: 收件微派 | O23: =VLOOKUP(C23,Sheet2!A:C,2,FALSE) -> 取宝-物流服务 | P23: =VLOOKUP(C23,Sheet2!G:H,2,FALSE) -> 134****6101 | Q23: 成都江源易通信息技术有限公司
A24: 22 | B24: 12-02 | C24: SF3295364078769 | D24: 雅安 | E24: 成都/资阳/眉山 | F24: 文刚 | G24: 0.000 | H24: 顺丰标快 | I24: 寄付 | J24: 6.00 | K24: 0.00 | L24: 6.00 | M24: 文刚 | N24: 收件微派 | O24: =VLOOKUP(C24,Sheet2!A:C,2,FALSE) -> 取宝-物流服务 | P24: =VLOOKUP(C24,Sheet2!G:H,2,FALSE) -> 134****6101 | Q24: 成都江源易通信息技术有限公司
A25: 23 | B25: 12-02 | C25: SF3295365022962 | D25: 东莞 | E25: 东莞 | F25: 邹小华 | G25: 0.000 | H25: 顺丰标快 | I25: 寄付 | J25: 3.00 | K25: 0.00 | L25: 3.00 | M25: 邹小华 | N25: 收件微派 | O25: =VLOOKUP(C25,Sheet2!A:C,2,FALSE) -> 立充充电宝取机柜-物流服务 | P25: =VLOOKUP(C25,Sheet2!G:H,2,FALSE) -> 186****6788 | Q25: 东莞市中汇信息技术有限公司
A26: 24 | B26: 12-02 | C26: SF3295365941133 | D26: 东莞 | E26: 东莞 | F26: 邹小华 | G26: 0.000 | H26: 顺丰标快 | I26: 寄付 | J26: 6.00 | K26: 0.00 | L26: 6.00 | M26: 邹小华 | N26: 收件微派 | O26: =VLOOKUP(C26,Sheet2!A:C,2,FALSE) -> 取宝-物流服务 | P26: =VLOOKUP(C26,Sheet2!G:H,2,FALSE) -> 186****6788 | Q26: 东莞市中汇信息技术有限公司
A27: 25 | B27: 12-03 | C27: SF3262004095424 | D27: 深圳 | E27: 东莞 | F27: 吴珊珊 | G27: 1.000 | H27: 顺丰标快 | I27: 寄转第三方 | J27: 13.00 | K27: 0.00 | L27: 13.00 | M27: 饶云普 | N27: 运费 | O27: =VLOOKUP(C27,Sheet2!A:C,2,FALSE) -> 立充充电宝取机柜-仅服务 | P27: =VLOOKUP(C27,Sheet2!G:H,2,FALSE) -> 130****4667 | Q27: 广东久益智付科技有限公司
A28: 26 | B28: 12-03 | C28: SF3262004095424 | D28: 深圳 | E28: 东莞 | F28: 吴珊珊 | G28: 0.000 | H28: 顺丰标快 | I28: 寄转第三方 | J28: 1.00 | K28: 0.00 | L28: 1.00 | M28: 饶云普 | N28: 包装服务 | O28: =VLOOKUP(C28,Sheet2!A:C,2,FALSE) -> 立充充电宝取机柜-仅服务 | P28: =VLOOKUP(C28,Sheet2!G:H,2,FALSE) -> 130****4667 | Q28: 广东久益智付科技有限公司
A29: 27 | B29: 12-03 | C29: SF3262004095497 | D29: 深圳 | E29: 东莞 | F29: 吴珊珊 | G29: 2.300 | H29: 顺丰标快 | I29: 寄转第三方 | J29: 16.00 | K29: 0.00 | L29: 16.00 | M29: 饶云普 | N29: 运费 | O29: =VLOOKUP(C29,Sheet2!A:C,2,FALSE) -> 立充充电宝取机柜-仅服务 | P29: =VLOOKUP(C29,Sheet2!G:H,2,FALSE) -> 130****4667 | Q29: 广东久益智付科技有限公司
A30: 28 | B30: 12-03 | C30: SF3262004095497 | D30: 深圳 | E30: 东莞 | F30: 吴珊珊 | G30: 0.000 | H30: 顺丰标快 | I30: 寄转第三方 | J30: 4.00 | K30: 0.00 | L30: 4.00 | M30: 饶云普 | N30: 包装服务 | O30: =VLOOKUP(C30,Sheet2!A:C,2,FALSE) -> 立充充电宝取机柜-仅服务 | P30: =VLOOKUP(C30,Sheet2!G:H,2,FALSE) -> 130****4667 | Q30: 广东久益智付科技有限公司
A31: 29 | B31: 12-03 | C31: SF3262004095742 | D31: 深圳 | E31: 东莞 | F31: 吴珊珊 | G31: 1.000 | H31: 顺丰标快 | I31: 寄转第三方 | J31: 13.00 | K31: 0.00 | L31: 13.00 | M31: 饶云普 | N31: 运费 | O31: =VLOOKUP(C31,Sheet2!A:C,2,FALSE) -> 立充充电宝取机柜-仅服务 | P31: =VLOOKUP(C31,Sheet2!G:H,2,FALSE) -> 130****4667 | Q31: 广东久益智付科技有限公司
A32: 30 | B32: 12-03 | C32: SF3262004095742 | D32: 深圳 | E32: 东莞 | F32: 吴珊珊 | G32: 0.000 | H32: 顺丰标快 | I32: 寄转第三方 | J32: 1.00 | K32: 0.00 | L32: 1.00 | M32: 饶云普 | N32: 包装服务 | O32: =VLOOKUP(C32,Sheet2!A:C,2,FALSE) -> 立充充电宝取机柜-仅服务 | P32: =VLOOKUP(C32,Sheet2!G:H,2,FALSE) -> 130****4667 | Q32: 广东久益智付科技有限公司
A33: 31 | B33: 12-03 | C33: SF3262004097071 | D33: 深圳 | E33: 东莞 | F33: 吴珊珊 | G33: 1.000 | H33: 顺丰标快 | I33: 寄转第三方 | J33: 13.00 | K33: 0.00 | L33: 13.00 | M33: 饶云普 | N33: 运费 | O33: =VLOOKUP(C33,Sheet2!A:C,2,FALSE) -> 立充充电宝取机柜-仅服务 | P33: =VLOOKUP(C33,Sheet2!G:H,2,FALSE) -> 130****4667 | Q33: 广东久益智付科技有限公司
... A213: 211 | B213: 12-15 | C213: SF3260488516087 | D213: 深圳 | E213: 东莞 | F213: 吴珊珊 | G213: 0.000 | H213: 顺丰标快 | I213: 寄转第三方 | J213: 1.00 | K213: 0.00 | L213: 1.00 | M213: 饶云普 | N213: 包装服务 | O213: =VLOOKUP(C213,Sheet2!A:C,2,FALSE) -> 立充充电宝取机柜-仅服务 | P213: =VLOOKUP(C213,Sheet2!G:H,2,FALSE) -> 130****4667 | Q213: 广东久益智付科技有限公司
A214: 212 | B214: 12-15 | C214: SF3260488516096 | D214: 深圳 | E214: 东莞 | F214: 吴珊珊 | G214: 9.800 | H214: 顺丰标快 | I214: 寄转第三方 | J214: 31.00 | K214: 0.00 | L214: 31.00 | M214: 饶云普 | N214: 运费 | O214: 立充充电宝取机柜-仅服务 | P214: =VLOOKUP(C214,Sheet2!G:H,2,FALSE) -> 130****4667 | Q214: 广东久益智付科技有限公司
A215: 213 | B215: 12-15 | C215: SF3260488516096 | D215: 深圳 | E215: 东莞 | F215: 吴珊珊 | G215: 0.000 | H215: 顺丰标快 | I215: 寄转第三方 | J215: 15.00 | K215: 0.00 | L215: 15.00 | M215: 饶云普 | N215: 包装服务 | O215: 立充充电宝取机柜-仅服务 | P215: =VLOOKUP(C215,Sheet2!G:H,2,FALSE) -> 130****4667 | Q215: 广东久益智付科技有限公司
A216: 214 | B216: 12-15 | C216: SF3260488516906 | D216: 深圳 | E216: 东莞 | F216: 吴珊珊 | G216: 1.000 | H216: 顺丰标快 | I216: 寄转第三方 | J216: 13.00 | K216: 0.00 | L216: 13.00 | M216: 饶云普 | N216: 运费 | O216: =VLOOKUP(C216,Sheet2!A:C,2,FALSE) -> 立充充电宝取机柜-仅服务 | P216: =VLOOKUP(C216,Sheet2!G:H,2,FALSE) -> 130****4667 | Q216: 广东久益智付科技有限公司
A217: 215 | B217: 12-15 | C217: SF3260488516906 | D217: 深圳 | E217: 东莞 | F217: 吴珊珊 | G217: 0.000 | H217: 顺丰标快 | I217: 寄转第三方 | J217: 1.00 | K217: 0.00 | L217: 1.00 | M217: 饶云普 | N217: 包装服务 | O217: =VLOOKUP(C217,Sheet2!A:C,2,FALSE) -> 立充充电宝取机柜-仅服务 | P217: =VLOOKUP(C217,Sheet2!G:H,2,FALSE) -> 130****4667 | Q217: 广东久益智付科技有限公司
A218: 216 | B218: 12-15 | C218: SF3260488516979 | D218: 深圳 | E218: 东莞 | F218: 吴珊珊 | G218: 1.000 | H218: 顺丰标快 | I218: 寄转第三方 | J218: 13.00 | K218: 0.00 | L218: 13.00 | M218: 饶云普 | N218: 运费 | O218: =VLOOKUP(C218,Sheet2!A:C,2,FALSE) -> 立充充电宝取机柜-仅服务 | P218: =VLOOKUP(C218,Sheet2!G:H,2,FALSE) -> 130****4667 | Q218: 广东久益智付科技有限公司
A219: 217 | B219: 12-15 | C219: SF3260488516979 | D219: 深圳 | E219: 东莞 | F219: 吴珊珊 | G219: 0.000 | H219: 顺丰标快 | I219: 寄转第三方 | J219: 1.00 | K219: 0.00 | L219: 1.00 | M219: 饶云普 | N219: 包装服务 | O219: =VLOOKUP(C219,Sheet2!A:C,2,FALSE) -> 立充充电宝取机柜-仅服务 | P219: =VLOOKUP(C219,Sheet2!G:H,2,FALSE) -> 130****4667 | Q219: 广东久益智付科技有限公司
A220: 218 | B220: 12-15 | C220: SF3260488518614 | D220: 深圳 | E220: 东莞 | F220: 吴珊珊 | G220: 3.000 | H220: 顺丰标快 | I220: 寄转第三方 | J220: 17.00 | K220: 0.00 | L220: 17.00 | M220: 饶云普 | N220: 运费 | O220: =VLOOKUP(C220,Sheet2!A:C,2,FALSE) -> 立充充电宝取机柜-仅服务 | P220: =VLOOKUP(C220,Sheet2!G:H,2,FALSE) -> 130****4667 | Q220: 广东久益智付科技有限公司
A221: 219 | B221: 12-15 | C221: SF3260488518614 | D221: 深圳 | E221: 东莞 | F221: 吴珊珊 | G221: 0.000 | H221: 顺丰标快 | I221: 寄转第三方 | J221: 5.00 | K221: 0.00 | L221: 5.00 | M221: 饶云普 | N221: 包装服务 | O221: =VLOOKUP(C221,Sheet2!A:C,2,FALSE) -> 立充充电宝取机柜-仅服务 | P221: =VLOOKUP(C221,Sheet2!G:H,2,FALSE) -> 130****4667 | Q221: 广东久益智付科技有限公司
A222: 220 | B222: 12-15 | C222: SF3260491849237 | D222: 成都/资阳/眉山 | E222: 成都/资阳/眉山 | F222: 周涛 | G222: 1.000 | H222: 顺丰标快 | I222: 寄转第三方 | J222: 11.00 | K222: 0.00 | L222: 11.00 | M222: 江源 | N222: 运费 | O222: =VLOOKUP(C222,Sheet2!A:C,2,FALSE) -> 补宝-物流服务 | P222: =VLOOKUP(C222,Sheet2!G:H,2,FALSE) -> 134****6101 | Q222: 成都江源易通信息技术有限公司
A223: 221 | B223: 12-15 | C223: SF3260491849334 | D223: 成都/资阳/眉山 | E223: 成都/资阳/眉山 | F223: 周涛 | G223: 1.000 | H223: 顺丰标快 | I223: 寄转第三方 | J223: 11.00 | K223: 0.00 | L223: 11.00 | M223: 江源 | N223: 运费 | O223: =VLOOKUP(C223,Sheet2!A:C,2,FALSE) -> 补宝-物流服务 | P223: =VLOOKUP(C223,Sheet2!G:H,2,FALSE) -> 134****6101 | Q223: 成都江源易通信息技术有限公司
A224: 222 | B224: 12-15 | C224: SF3260499115096 | D224: 成都/资阳/眉山 | E224: 成都/资阳/眉山 | F224: 代俊峰 | G224: 1.000 | H224: 顺丰标快 | I224: 寄转第三方 | J224: 11.00 | K224: 0.00 | L224: 11.00 | M224: 代俊峰 | N224: 运费 | O224: =VLOOKUP(C224,Sheet2!A:C,2,FALSE) -> 补宝-物流服务 | P224: =VLOOKUP(C224,Sheet2!G:H,2,FALSE) -> 134****6101 | Q224: 成都江源易通信息技术有限公司
...

Sheet 月结报告

Sheet 12月订单明细
A1: 运单号 | B1: 任务类型 | C1: 系统订单号 | D1: 照片是否导出 | E1: 批次号 | F1: 服务状态 | G1: 商户订单号 | H1: 上门小哥手机号 | I1: 物流状态 | J1: 是否打印 | K1: 预计上门时间 | L1: 收件人 | M1: 收件手机 | N1: 收件电话 | O1: 收件公司 | P1: 收件详细地址 | Q1: 寄件人 | R1: 寄件电话 | S1: 寄方备注 | T1: 寄件公司 | U1: 寄件详细地址 | V1: 托寄物内容 | W1: 托寄物数量 | X1: 件数 | Y1: 包裹重量(kg) | Z1: 运费付款方式 | AA1: 物流产品 | AB1: 自取 | AC1: 定额保价金额(元) | AD1: 基础保价金额(元) | AE1: 密钥认证 | AF1: 下单时间 | AG1: 下单账号 | AH1: 接单人姓名 | AI1: 任务完成时间 | AJ1: 接单人手机 | AK1: 签收完成时间 | AL1: 月结卡号 | AM1: 下call上门收件 | AN1: 标记 | AO1: 异常原因
A2: SF3268579296831 | B2: 补宝-物流服务 | C2: WP25123087228645 | D2: 未导出 | E2: BAT251230092439 | F2: 待接单 | I2: 未收件 | J2: 未打印 | L2: 唐*满 | M2: 155****0885‎‎‎‬‬‬ | N2: *******0885‎‎‎‬‬‬ | O2: 大连浩源********* | P2: 辽宁省大 连市金州区***********‎‎‎‬‬‬ | Q2: 孙*达 | R2: *******6213‎‎‎‬‬‬ | T2: 达叔烤骨头 | U2: 大连市普兰店区**** ************‎‎‎‬‬‬ | V2: 充电宝 | W2: 1 | X2: 1 | Y2: 1 | Z2: 第三方付 | AA2: 顺丰特快 | AE2: 否 | AF2: 2025-12-30 13:46:23 | AG2: 155****0885 | AL2: 7551083218 | AM2: 是
A3: SF3268579291750 | B3: 补宝-物流服务 | C3: WP25123087226877 | D3: 未导出 | E3: BAT251230092259 | F3: 待接单 | I3: 未收件 | J3: 未打印 | L3: 唐*满 | M3: 155****0885‎‎‎‬‬‬ | N3: *******0885‎‎‎‬‬‬ | O3: 大连浩源********* | P3: 辽宁省大 连市金州区***********‎‎‎‬‬‬ | Q3: 孙*达 | R3: *******6213‎‎‎‬‬‬ | U3: 大连市普兰店区**** ************‎‎‎‬‬‬ | V3: 充电柜 | W3: 1 | X3: 1 | Y3: 5 | Z3: 第三方付 | AA3: 顺丰特快 | AE3: 否 | AF3: 2025-12-30 13:46:23 | AG3: 155****0885 | AL3: 7551083218 | AM3: 是
A4: SF5127709690867 | B4: 补宝-物流服务 | C4: WP25123087225294 | D4: 未导出 | E4: BAT251230092044 | F4: 待接单 | I4: 未收件 | J4: 未打印 | L4: 唐*满 | M4: 155****0885‎‎‎‬‬‬ | N4: *******0885‎‎‎‬‬‬ | O4: 大连浩源********* | P4: 辽宁省大 连市金州区***********‎‎‎‬‬‬ | Q4: 孙*达 | R4: *******6213‎‎‎‬‬‬ | T4: 达叔烤骨头 | U4: 大连市普兰店区**** ************‎‎‎‬‬‬ | V4: 充电宝 | W4: 2 | X4: 1 | Y4: 1 | Z4: 第三方付 | AA4: 顺丰特快 | AE4: 否 | AF4: 2025-12-30 13:46:23 | AG4: 155****0885 | AL4: 7551083218 | AM4: 是
A5: SF5106905852824 | B5: 补宝-物流服务 | C5: WP25123087222064 | D5: 未导出 | E5: BAT251230091695 | F5: 待接单 | I5: 未收件 | J5: 未打印 | L5: 唐*满 | M5: 155****0885‎‎‎‬‬‬ | O5: 大连浩源********* | P5: 辽宁省大 连市金州区***********‎‎‎‬‬‬ | Q5: 孙*达 | R5: *******6213‎‎‎‬‬‬ | T5: 达叔烤骨头 | U5: 大连市普兰店区**** ************‎‎‎‬‬‬ | V5: 充电宝 | W5: 2 | X5: 1 | Y5: 1 | Z5: 第三方付 | AA5: 顺丰特快 | AC5: 500 | AE5: 否 | AF5: 2025-12-30 13:46:23 | AG5: 155****0885 | AL5: 7551083218 | AM5: 是
A6: SF5105056503415 | B6: 补宝-物流服务 | C6: WP25122253862488 | D6: 未导出 | E6: BAT251222071369 | F6: 已完成 | I6: 派送成功 | J6: 未打印 | K6: 2025-12-23 12:00 | L6: 李*云 | M6: 181****7580‎‎‎‬‬‬ | P6: 四川省雅安市雨城区***** ****‎‎‎‬‬‬ | Q6: 江* | R6: *******6925‎‎‎‬‬‬ | U6: 四川省成都市 武侯区*****************‎‎‎‬‬‬ | V6: 充电宝 | W6: 2 | X6: 1 | Z6: 寄付月结 | AA6: 顺丰标快 | AE6: 否 | AF6: 2025-12-22 14:08:09 | AG6: 134****6101 | AH6: 穆赵超 | AI6: 2025-12-23 09:24:01 | AJ6: 150****2907‎‎‎‬‬‬ | AK6: 2025-12-23 09:24:06 | AL6: 7551083218 | AM6: 否
A7: SF5105056506251 | B7: 补宝-物流服务 | C7: WP25122253859962 | D7: 未导出 | E7: BAT251222071098 | F7: 已完成 | I7: 派送成功 | J7: 未打印 | K7: 2025-12-23 12:00 | L7: 李*云 | M7: 181****7580‎‎‎‬‬‬ | P7: 四川省雅安市雨城区***** ****‎‎‎‬‬‬ | Q7: 江* | R7: *******6925‎‎‎‬‬‬ | U7: 四川省成都市 武侯区*****************‎‎‎‬‬‬ | V7: 充电宝 | W7: 2 | X7: 1 | Z7: 寄付月结 | AA7: 顺丰标快 | AE7: 否 | AF7: 2025-12-22 14:08:09 | AG7: 134****6101 | AH7: 穆赵超 | AI7: 2025-12-23 09:24:30 | AJ7: 150****2907‎‎‎‬‬‬ | AK7: 2025-12-23 09:24:37 | AL7: 7551083218 | AM7: 否
A8: SF3266863453181 | B8: 补宝-物流服务 | C8: WP25122253857124 | D8: 未导出 | E8: BAT251222070775 | F8: 已完成 | I8: 派送成功 | J8: 未打印 | K8: 2025-12-23 12:00 | L8: 李*云 | M8: 181****7580‎‎‎‬‬‬ | P8: 四川省雅安市雨城区***** ****‎‎‎‬‬‬ | Q8: 江* | R8: *******6925‎‎‎‬‬‬ | S8: 24100081244 | U8: 四川省成都市 武侯区*****************‎‎‎‬‬‬ | V8: 充电宝 | W8: 1 | X8: 1 | Z8: 寄付月结 | AA8: 顺丰标快 | AE8: 否 | AF8: 2025-12-22 14:08:09 | AG8: 134****6101 | AH8: 穆赵超 | AI8: 2025-12-23 09:23:08 | AJ8: 150****2907‎‎‎‬‬‬ | AK8: 2025-12-23 09:23:15 | AL8: 7551083218 | AM8: 否
A9: SF3261464758524 | B9: 补宝-物流服务 | C9: WP25121840418840 | D9: 未导出 | E9: BAT251218185468 | F9: 已完成 | I9: 派送成功 | J9: 未打印 | L9: 邹*华 | M9: 186****6788‎‎‎‬‬‬ | N9: *******6788‎‎‎‬‬‬ | O9: 清溪美宜********** | P9: 广东省 东莞市清溪镇********************‎‎‎‬‬‬ | Q9: 邹*华 | R9: *******6788‎‎‎‬‬‬ | S9: 进店补立充充电宝的宝1个 | U9: 广东省东莞市东城街道东纵路东城段208号 东城万达中心写**********‎‎‎‬‬‬ | V9: 充电宝 | W9: 1 | X9: 1 | Z9: 寄付月结 | AA9: 顺丰标快 | AE9: 否 | AF9: 2025-12-18 16:37:18 | AG9: 186****6788 | AH9: 黄定平 | AI9: 2025-12-19 09:27:31 | AJ9: 132****1601‎‎‎‬‬‬ | AK9: 2025-12-19 09:28:32 | AL9: 7551083218 | AM9: 是
A10: SF3261464758781 | B10: 补宝-物流服务 | C10: WP25121840414211 | D10: 未导出 | E10: BAT251218184998 | F10: 已完成 | I10: 派送成功 | J10: 未打印 | L10: 邹*华 | M10: 186****6788‎‎‎‬‬‬ | N10: *******6788‎‎‎‬‬‬ | O10: 清溪美宜********** | P10: 广东省 东莞市清溪镇********************‎‎‎‬‬‬ | Q10: 邹*华 | R10: *******6788‎‎‎‬‬‬ | S10: 进店补立充充电宝的宝2个 | U10: 广东省东莞市东城街道东纵路东城段208号 东城万达中心写**********‎‎‎‬‬‬ | V10: 充电宝 | W10: 2 | X10: 1 | Z10: 寄付月结 | AA10: 顺丰标快 | AE10: 否 | AF10: 2025-12-18 16:37:18 | AG10: 186****6788 | AH10: 张直国 | AI10: 2025-12-19 09:15:13 | AJ10: 131****3365‎‎‎‬‬‬ | AK10: 2025-12-19 09:15:31 | AL10: 7551083218 | AM10: 是
A11: SF3261417303446 | B11: 补宝-物流服务 | C11: WP25121840198092 | D11: 未导出 | E11: BAT251218163193 | F11: 已完成 | I11: 派送成功 | J11: 未打印 | K11: 2025-12-19 12:00 | L11: 老* | M11: 152****5518‎‎‎‬‬‬ | P11: 都江堰市 观景路483**********‎‎‎‬‬‬ | Q11: 江* | R11: *******5357‎‎‎‬‬‬ | U11: 四川省成都市 武侯区*****************‎‎‎‬‬‬ | V11: 充电宝 | W11: 2 | X11: 1 | Z11: 寄付月结 | AA11: 顺丰标快 | AE11: 否 | AF11: 2025-12-18 16:06:35 | AG11: 134****6101 | AH11: 孟俊涛 | AI11: 2025-12-20 19:42:07 | AJ11: 177****7352‎‎‎‬‬‬ | AK11: 2025-12-20 19:42:17 | AL11: 7551083218 | AM11: 否
A12: SF3261417303058 | B12: 补宝-物流服务 | C12: WP25121840196464 | D12: 未导出 | E12: BAT251218163017 | F12: 已完成 | I12: 派送成功 | J12: 未打印 | K12: 2025-12-19 12:00 | L12: 老* | M12: 152****5518‎‎‎‬‬‬ | P12: 都江堰市 观景路483**********‎‎‎‬‬‬ | Q12: 江* | R12: *******5357‎‎‎‬‬‬ | U12: 四川省成都市 武侯区*****************‎‎‎‬‬‬ | V12: 充电宝 | W12: 2 | X12: 1 | Z12: 寄付月结 | AA12: 顺丰标快 | AE12: 否 | AF12: 2025-12-18 16:06:35 | AG12: 134****6101 | AH12: 孟俊涛 | AI12: 2025-12-20 19:43:08 | AJ12: 177****7352‎‎‎‬‬‬ | AK12: 2025-12-20 19:43:13 | AL12: 7551083218 | AM12: 否
A13: SF3261282600597 | B13: 补宝-物流服务 | C13: WP25121629308215 | D13: 未导出 | E13: BAT251216021950 | F13: 已完成 | I13: 派送成功 | J13: 未打印 | K13: 2025-12-17 12:00 | L13: 刘* | M13: 135****7686‎‎‎‬‬‬ | N13: *******7686‎‎‎‬‬‬ | P13: 四川省成都市武侯区************ **‎‎‎‬‬‬ | Q13: 江* | R13: *******5357‎‎‎‬‬‬ | S13: 补宝机身号：23090013991 | U13: 四川省成都市 武侯区*****************‎‎‎‬‬‬ | V13: 充电宝 | W13: 1 | X13: 1 | Z13: 寄付月结 | AA13: 顺丰即日 | AE13: 否 | AF13: 2025-12-16 09:21:02 | AG13: 134****6101 | AH13: 马兴龙 | AI13: 2025-12-16 16:40:35 | AJ13: 191****7127‎‎‎‬‬‬ | AK13: 2025-12-16 16:40:41 | AL13: 7551083218 | AM13: 是
A14: SF3260491849334 | B14: 补宝-物流服务 | C14: WP25121525331090 | D14: 未导出 | E14: BAT251215106641 | F14: 已完成 | I14: 派送成功 | J14: 未打印 | K14: 2025-12-16 12:00 | L14: 周* | M14: 158****0900‎‎‎‬‬‬ | P14: 四川省成都市金牛区*********** **‎‎‎‬‬‬ | Q14: 江* | R14: *******5357‎‎‎‬‬‬ | S14: 补宝机身号： 24040036300 | U14: 四川省成都市 武侯区*****************‎‎‎‬‬‬ | V14: 充电宝 | W14: 1 | X14: 1 | Z14: 寄付月结 | AA14: 顺丰标快 | AE14: 否 | AF14: 2025-12-15 14:18:49 | AG14: 134****6101 | AH14: 杨飞 | AI14: 2025-12-16 09:48:57 | AJ14: 173****8035‎‎‎‬‬‬ | AK14: 2025-12-16 09:49:21 | AL14: 7551083218 | AM14: 是
A15: SF3260491849237 | B15: 补宝-物流服务 | C15: WP25121525329098 | D15: 未导出 | E15: BAT251215106408 | F15: 已完成 | I15: 派送成功 | J15: 未打印 | K15: 2025-12-16 12:00 | L15: 周* | M15: 158****0900‎‎‎‬‬‬ | P15: 四川省成都市金牛区*********** **‎‎‎‬‬‬ | Q15: 江* | R15: *******5357‎‎‎‬‬‬ | S15: 补宝机身号： 24040036300 | U15: 四川省成都市 武侯区*****************‎‎‎‬‬‬ | V15: 充电宝 | W15: 2 | X15: 1 | Z15: 寄付月结 | AA15: 顺丰标快 | AE15: 否 | AF15: 2025-12-15 14:18:49 | AG15: 134****6101 | AH15: 杨飞 | AI15: 2025-12-16 09:47:55 | AJ15: 173****8035‎‎‎‬‬‬ | AK15: 2025-12-16 09:48:01 | AL15: 7551083218 | AM15: 是
A16: SF3260420814593 | B16: 补宝-物流服务 | C16: WP25121525237467 | D16: 未导出 | E16: BAT251215096732 | F16: 待接单 | I16: 未收件 | J16: 未打印 | L16: 乔* | N16: *******5919‎‎‎‬‬‬ | O16: 天津三有****** | P16: 河北省廊坊市固安县***** **********‎‎‎‬‬‬ | Q16: 闫 | R16: *******8837‎‎‎‬‬‬ | U16: 北京市大兴区**************** **************‎‎‎‬‬‬ | V16: 立充机柜 | W16: 1 | X16: 1 | Z16: 寄付月结 | AA16: 顺丰标快 | AE16: 否 | AF16: 2025-12-15 13:55:27 | AG16: 136****7868 | AL16: 7551083218 | AM16: 是
A17: SF3260499115096 | B17: 补宝-物流服务 | C17: WP25121524879952 | D17: 未导出 | E17: BAT251215058005 | F17: 已完成 | I17: 派送成功 | J17: 未打印 | K17: 2025-12-16 12:00 | L17: 代*峰 | M17: 186****8030‎‎‎‬‬‬ | N17: *******8030‎‎‎‬‬‬ | P17: 四川省成都市成华区********************** ************‎‎‎‬‬‬ | Q17: 代*峰 | R17: *******8030‎‎‎‬‬‬ | S17: 补宝机柜：24100081048 | U17: 四川省成都市 郫都区*******‎‎‎‬‬‬ | V17: 充电宝 | W17: 1 | X17: 1 | Z17: 寄付月结 | AA17: 顺丰标快 | AE17: 否 | AF17: 2025-12-15 14:13:51 | AG17: 134****6101 | AH17: 刘银豪 | AI17: 2025-12-15 20:37:35 | AJ17: 177****9764‎‎‎‬‬‬ | AK17: 2025-12-15 20:37:46 | AL17: 7551083218 | AM17: 是
A18: SF3260499115906 | B18: 补宝-物流服务 | C18: WP25121524873236 | D18: 未导出 | E18: BAT251215057306 | F18: 已完成 | I18: 派送成功 | J18: 未打印 | K18: 2025-12-16 12:00 | L18: 代*峰 | M18: 186****8030‎‎‎‬‬‬ | N18: *******8030‎‎‎‬‬‬ | P18: 成华区********** *************************‎‎‎‬‬‬ | Q18: 代*峰 | R18: *******8030‎‎‎‬‬‬ | S18: 补宝机柜号：24100081048 | U18: 四川省成都市 郫都区*******‎‎‎‬‬‬ | V18: 充电宝 | W18: 2 | X18: 1 | Z18: 寄付月结 | AA18: 顺丰标快 | AE18: 否 | AF18: 2025-12-15 14:13:51 | AG18: 134****6101 | AH18: 刘银豪 | AI18: 2025-12-15 20:39:01 | AJ18: 177****9764‎‎‎‬‬‬ | AK18: 2025-12-15 20:39:09 | AL18: 7551083218 | AM18: 是
A19: SF3278405753506 | B19: 补宝-物流服务 | C19: WP25121108634270 | D19: 未导出 | E19: BAT251211042008 | F19: 已完成 | I19: 派送成功 | J19: 未打印 | K19: 2025-12-12 12:00 | L19: 邹*华 | M19: 186****6788‎‎‎‬‬‬ | N19: *******6788‎‎‎‬‬‬ | O19: 高埗稻田***** | P19: 广东省东莞市高埗镇*********** *****************‎‎‎‬‬‬ | Q19: 邹*华 | R19: *******6788‎‎‎‬‬‬ | S19: 进店补立充充电宝的宝1个 | U19: 广东省东莞市东城街道东纵路东城段208号 东城万达中心写**********‎‎‎‬‬‬ | V19: 充电宝 | W19: 1 | X19: 1 | Z19: 寄付月结 | AA19: 顺丰标快 | AE19: 否 | AF19: 2025-12-11 10:27:22 | AG19: 186****6788 | AH19: 李亮 | AI19: 2025-12-11 17:34:56 | AJ19: 186****3894‎‎‎‬‬‬ | AK19: 2025-12-11 17:35:29 | AL19: 7551083218 | AM19: 是
A20: SF3278434363447 | B20: 补宝-物流服务 | C20: WP25121108476885 | D20: 未导出 | E20: BAT251211024420 | F20: 已完成 | I20: 派送成功 | J20: 未打印 | K20: 2025-12-12 12:00 | L20: 邹*华 | M20: 186****6788‎‎‎‬‬‬ | N20: *******6788‎‎‎‬‬‬ | O20: 寮步****** | P20: 广东省东莞市寮步 镇*********‎‎‎‬‬‬ | Q20: 邹*华 | R20: *******6788‎‎‎‬‬‬ | S20: 进店补立充充电宝的宝2个 | U20: 广东省东莞市东城街道东纵路东城段208号 东城万达中心写**********‎‎‎‬‬‬ | V20: 充电宝 | W20: 2 | X20: 1 | Z20: 寄付月结 | AA20: 顺丰标快 | AE20: 否 | AF20: 2025-12-11 09:28:59 | AG20: 186****6788 | AH20: 庄龙生 | AI20: 2025-12-11 17:06:43 | AJ20: 132****2205‎‎‎‬‬‬ | AK20: 2025-12-11 17:06:55 | AL20: 7551083218 | AM20: 是
A21: SF3278434363483 | B21: 补宝-物流服务 | C21: WP25121108475411 | D21: 未导出 | E21: BAT251211024253 | F21: 已完成 | I21: 派送成功 | J21: 未打印 | K21: 2025-12-12 12:00 | L21: 邹*华 | M21: 186****6788‎‎‎‬‬‬ | N21: *******6788‎‎‎‬‬‬ | O21: 高埗稻田***** | P21: 广东省东莞市高埗镇*********** *****************‎‎‎‬‬‬ | Q21: 邹*华 | R21: *******6788‎‎‎‬‬‬ | S21: 进店补立充充电宝的宝3个 | U21: 广东省东莞市东城街道东纵路东城段208号 东城万达中心写**********‎‎‎‬‬‬ | V21: 充电宝 | W21: 3 | X21: 1 | Z21: 寄付月结 | AA21: 顺丰标快 | AE21: 否 | AF21: 2025-12-11 09:28:59 | AG21: 186****6788 | AH21: 李亮 | AI21: 2025-12-11 17:37:01 | AJ21: 186****3894‎‎‎‬‬‬ | AK21: 2025-12-11 17:37:39 | AL21: 7551083218 | AM21: 是
A22: SF3269834853653 | B22: 补宝-物流服务 | C22: WP25121108472079 | D22: 未导出 | E22: BAT251211024149 | F22: 已完成 | I22: 派送成功 | J22: 未打印 | K22: 2025-12-12 12:00 | L22: 邹*华 | M22: 186****6788‎‎‎‬‬‬ | N22: *******6788‎‎‎‬‬‬ | O22: 企石凯迪******* | P22: 广东省东莞市企石 **********‎‎‎‬‬‬ | Q22: 邹*华 | R22: *******6788‎‎‎‬‬‬ | S22: 进店补立充充电宝的宝2个 | U22: 广东省东莞市东城街道东纵路东城段208号 东城万达中心写**********‎‎‎‬‬‬ | V22: 充电宝 | W22: 2 | X22: 1 | Z22: 寄付月结 | AA22: 顺丰标快 | AE22: 否 | AF22: 2025-12-11 09:28:59 | AG22: 186****6788 | AH22: 李立华 | AI22: 2025-12-11 17:53:00 | AJ22: 136****4147‎‎‎‬‬‬ | AK22: 2025-12-11 17:53:22 | AL22: 7551083218 | AM22: 是
A23: SF3269042397254 | B23: 补宝-物流服务 | C23: WP25120902973697 | D23: 未导出 | E23: BAT251209504158 | F23: 已完成 | I23: 派送成功 | J23: 未打印 | L23: 罗* | M23: 181****6669‎‎‎‬‬‬ | N23: *******6669‎‎‎‬‬‬ | P23: 广东省深圳市宝安区* ************************‎‎‎‬‬‬ | Q23: 吴*继 | R23: *******6168‎‎‎‬‬‬ | T23: 广东久益智付科技有限公司 | U23: 广东省东莞市南城 **********‎‎‎‬‬‬ | V23: 立充充电宝 | W23: 1 | X23: 1 | Z23: 寄付月结 | AA23: 顺丰标快 | AE23: 否 | AF23: 2025-12-09 22:16:31 | AG23: 130****4667 | AH23: 丘春生 | AI23: 2025-12-11 09:56:57 | AJ23: 139****6926‎‎‎‬‬‬ | AK23: 2025-12-11 09:57:06 | AL23: 7551083218 | AM23: 是
A24: SF3269933113650 | B24: 补宝-物流服务 | C24: WP25120895414076 | D24: 未导出 | E24: BAT251208277541 | F24: 已完成 | I24: 派送成功 | J24: 未打印 | K24: 2025-12-09 12:00 | L24: 邹*华 | M24: 186****6788‎‎‎‬‬‬ | N24: *******6788‎‎‎‬‬‬ | O24: 洪梅湘味***** | P24: 广东省东莞市洪梅镇***************** **‎‎‎‬‬‬ | Q24: 邹*华 | R24: *******6788‎‎‎‬‬‬ | S24: 进店补立充充电宝的宝1个 | U24: 广东省东莞市东城街道东纵路东城段208号 东城万达中心写**********‎‎‎‬‬‬ | V24: 充电宝 | W24: 1 | X24: 1 | Z24: 寄付月结 | AA24: 顺丰标快 | AE24: 否 | AF24: 2025-12-08 17:26:58 | AG24: 186****6788 | AH24: 苏洁 | AI24: 2025-12-09 10:27:06 | AJ24: 158****3232‎‎‎‬‬‬ | AK24: 2025-12-09 10:27:10 | AL24: 7551083218 | AM24: 是
A25: SF3278126546304 | B25: 补宝-物流服务 | C25: WP25120895409404 | D25: 未导出 | E25: BAT251208277033 | F25: 已完成 | I25: 派送成功 | J25: 未打印 | L25: 邹*华 | M25: 186****6788‎‎‎‬‬‬ | N25: *******6788‎‎‎‬‬‬ | O25: 洪梅湘味***** | P25: 广东省东莞市洪梅镇***************** **‎‎‎‬‬‬ | Q25: 邹*华 | R25: *******6788‎‎‎‬‬‬ | S25: 进店补立充充电宝的宝2个 | U25: 广东省东莞市东城街道东纵路东城段208号 东城万达中心写**********‎‎‎‬‬‬ | V25: 充电宝 | W25: 2 | X25: 1 | Z25: 寄付月结 | AA25: 顺丰标快 | AE25: 否 | AF25: 2025-12-08 17:26:58 | AG25: 186****6788 | AH25: 苏洁 | AI25: 2025-12-09 10:26:25 | AJ25: 158****3232‎‎‎‬‬‬ | AK25: 2025-12-09 10:26:30 | AL25: 7551083218 | AM25: 是
A26: SF3269248082701 | B26: 补宝-物流服务 | C26: WP25120895195768 | D26: 未导出 | E26: BAT251208255813 | F26: 已完成 | I26: 派送成功 | J26: 未打印 | K26: 2025-12-09 12:00 | L26: 邹*华 | M26: 186****6788‎‎‎‬‬‬ | N26: *******6788‎‎‎‬‬‬ | O26: 石碣****** | P26: 广东省东莞市石 碣镇**********************‎‎‎‬‬‬ | Q26: 邹*华 | R26: *******6788‎‎‎‬‬‬ | S26: 进店取立充充电宝2个 | U26: 广东省东莞市东城街道东纵路东城段208号 东城万达中心写**********‎‎‎‬‬‬ | V26: 充电宝 | W26: 2 | X26: 1 | Z26: 寄付月结 | AA26: 顺丰标快 | AE26: 否 | AF26: 2025-12-08 17:06:18 | AG26: 186****6788 | AH26: 冉江林 | AI26: 2025-12-09 10:51:16 | AJ26: 189****8452‎‎‎‬‬‬ | AK26: 2025-12-09 10:51:29 | AL26: 7551083218 | AM26: 是
A27: SF3269246608556 | B27: 补宝-物流服务 | C27: WP25120895158153 | D27: 未导出 | E27: BAT251208251915 | F27: 已完成 | I27: 派送成功 | J27: 未打印 | K27: 2025-12-09 12:00 | L27: 邹*华 | M27: 186****6788‎‎‎‬‬‬ | N27: *******6788‎‎‎‬‬‬ | O27: 常平**** | P27: 广东省东莞市常平 镇*********‎‎‎‬‬‬ | Q27: 邹*华 | R27: *******6788‎‎‎‬‬‬ | S27: 进店补立充充电宝的宝2个 | U27: 广东省东莞市东城街道东纵路东城段208号 东城万达中心写**********‎‎‎‬‬‬ | V27: 充电宝 | W27: 2 | X27: 1 | Z27: 寄付月结 | AA27: 顺丰标快 | AE27: 否 | AF27: 2025-12-08 17:02:57 | AG27: 186****6788 | AH27: 周乐义 | AI27: 2025-12-09 09:56:55 | AJ27: 136****8851‎‎‎‬‬‬ | AK27: 2025-12-09 09:57:18 | AL27: 7551083218 | AM27: 是
A28: SF3278179778744 | B28: 补宝-物流服务 | C28: WP25120895129612 | D28: 未导出 | E28: BAT251208248948 | F28: 已完成 | I28: 派送成功 | J28: 未打印 | K28: 2025-12-09 12:00 | L28: 邹*华 | M28: 186****6788‎‎‎‬‬‬ | N28: *******6788‎‎‎‬‬‬ | O28: 大岭山五******* | P28: 广东省东莞市大岭山镇 ************************‎‎‎‬‬‬ | Q28: 邹*华 | R28: *******6788‎‎‎‬‬‬ | S28: 进店补立充充电宝的宝2个 | U28: 广东省东莞市东城街道东纵路东城段208号 东城万达中心写**********‎‎‎‬‬‬ | V28: 充电宝 | W28: 2 | X28: 1 | Z28: 寄付月结 | AA28: 顺丰标快 | AE28: 否 | AF28: 2025-12-08 16:59:57 | AG28: 186****6788 | AH28: 周洋 | AI28: 2025-12-09 14:49:30 | AJ28: 186****5265‎‎‎‬‬‬ | AK28: 2025-12-09 14:49:40 | AL28: 7551083218 | AM28: 是
A29: SF3269241885700 | B29: 补宝-物流服务 | C29: WP25120895120790 | D29: 未导出 | E29: BAT251208248056 | F29: 已完成 | I29: 派送成功 | J29: 未打印 | K29: 2025-12-09 12:00 | L29: 邹*华 | M29: 186****6788‎‎‎‬‬‬ | N29: *******6788‎‎‎‬‬‬ | O29: 寮步四个*************** | P29: 广东省东莞 市寮步镇************‎‎‎‬‬‬ | Q29: 邹*华 | R29: *******6788‎‎‎‬‬‬ | S29: 进店取立充的充电宝的宝2个 | U29: 广东省东莞市东城街道东纵路东城段208号 东城万达中心写**********‎‎‎‬‬‬ | V29: 充电宝 | W29: 1 | X29: 1 | Z29: 寄付月结 | AA29: 顺丰标快 | AE29: 否 | AF29: 2025-12-08 16:59:57 | AG29: 186****6788 | AH29: 孙剑 | AI29: 2025-12-09 10:42:47 | AJ29: 157****3657‎‎‎‬‬‬ | AK29: 2025-12-09 10:43:03 | AL29: 7551083218 | AM29: 是
A30: SF3269240753364 | B30: 补宝-物流服务 | C30: WP25120895103995 | D30: 未导出 | E30: BAT251208246383 | F30: 已完成 | I30: 派送成功 | J30: 未打印 | K30: 2025-12-09 12:00 | L30: 邹*华 | M30: 186****6788‎‎‎‬‬‬ | N30: *******6788‎‎‎‬‬‬ | O30: 企石好想******** | P30: 广东省东莞 市企石镇************‎‎‎‬‬‬ | Q30: 邹*华 | R30: *******6788‎‎‎‬‬‬ | S30: 进店补立充充电宝的宝2个 | U30: 广东省东莞市东城街道东纵路东城段208号 东城万达中心写**********‎‎‎‬‬‬ | V30: 充电宝 | W30: 2 | X30: 1 | Z30: 寄付月结 | AA30: 顺丰标快 | AE30: 否 | AF30: 2025-12-08 16:56:42 | AG30: 186****6788 | AH30: 胡佳琪 | AI30: 2025-12-09 08:54:53 | AJ30: 151****3972‎‎‎‬‬‬ | AK30: 2025-12-09 08:55:13 | AL30: 7551083218 | AM30: 是
A31: SF3269276252803 | B31: 补宝-物流服务 | C31: WP25120894815169 | D31: 未导出 | E31: BAT251208216282 | F31: 已取消 | I31: 未收件 | J31: 未打印 | L31: 邹*华 | M31: 186****6788‎‎‎‬‬‬ | N31: *******6788‎‎‎‬‬‬ | O31: 洪梅湘味***** | P31: 广东省东莞市洪梅镇***************** **‎‎‎‬‬‬ | Q31: 邹*华 | R31: *******6788‎‎‎‬‬‬ | S31: 进店补立充充电宝的宝2个 | U31: 广东省东莞市东城街道东纵路东城段208号 东城万达中心写**********‎‎‎‬‬‬ | V31: 充电宝 | W31: 2 | X31: 1 | Z31: 寄付月结 | AA31: 顺丰标快 | AE31: 否 | AF31: 2025-12-08 16:21:05 | AG31: 186****6788 | AL31: 7551083218 | AM31: 是
A32: SF3274990520130 | B32: 补宝-物流服务 | C32: WP25120373167360 | D32: 未导出 | E32: BAT251203136179 | F32: 已完成 | I32: 派送成功 | J32: 未打印 | K32: 2025-12-04 12:00 | L32: 邹*华 | M32: 186****6788‎‎‎‬‬‬ | N32: *******6788‎‎‎‬‬‬ | O32: 石湾美宜***************** | P32: 广东省惠州市博罗县*** **************‎‎‎‬‬‬ | Q32: 邹*华 | R32: *******6788‎‎‎‬‬‬ | S32: 进店补立充充电宝的宝2个 | U32: 广东省东莞市东城街道东纵路东城段208号 东城万达中心写**********‎‎‎‬‬‬ | V32: 充电宝 | W32: 2 | X32: 1 | Z32: 寄付月结 | AA32: 顺丰标快 | AE32: 否 | AF32: 2025-12-03 14:34:58 | AG32: 186****6788 | AH32: 苏永富 | AI32: 2025-12-04 11:09:54 | AJ32: 135****4319‎‎‎‬‬‬ | AK32: 2025-12-04 11:10:07 | AL32: 7551083218 | AM32: 是
A33: SF3268714509952 | B33: 取宝-物流服务 | C33: WP25123190773889 | D33: 未导出 | E33: BAT251231026646 | F33: 已完成 | H33: 15013577157 | I33: 派送成功 | J33: 未打印 | K33: 2026-01-01 12:00 | L33: 邹*华 | M33: 186****6788‎‎‎‬‬‬ | N33: *******6788‎‎‎‬‬‬ | P33: 广东省东莞市东城街道东纵路东城段208号 东城万达中心写**********‎‎‎‬‬‬ | Q33: 邹*华 | R33: *******6788‎‎‎‬‬‬ | S33: 进店取立充充电宝的宝3个 | T33: 小云乡·云南菜(长安店) | U33: 广东省东莞 市长安镇************‎‎‎‬‬‬ | V33: 充电宝 | W33: 3 | X33: 1 | Z33: 寄付月结 | AA33: 顺丰标快 | AE33: 否 | AF33: 2025-12-31 10:08:00 | AG33: 186****6788 | AH33: 蔡李任 | AI33: 2025-12-31 12:14:55 | AJ33: 150****7157‎‎‎‬‬‬ | AK33: 2026-01-01 09:00:03 | AL33: 7551083218 | AM33: 是
A34: SF5127754205822 | B34: 取宝-物流服务 | C34: WP25123190772209 | D34: 未导出 | E34: BAT251231026472 | F34: 已完成 | H34: 15013577157 | I34: 派送成功 | J34: 未打印 | K34: 2026-01-01 12:00 | L34: 邹*华 | M34: 186****6788‎‎‎‬‬‬ | N34: *******6788‎‎‎‬‬‬ | P34: 广东省东莞市东城街道东纵路东城段208号 东城万达中心写**********‎‎‎‬‬‬ | Q34: 邹*华 | R34: *******6788‎‎‎‬‬‬ | S34: 进店取立充充电宝的宝2个 | T34: 小云乡·云南菜(长安店) | U34: 广东省东莞 市长安镇************‎‎‎‬‬‬ | V34: 充电宝 | W34: 2 | X34: 1 | Z34: 寄付月结 | AA34: 顺丰标快 | AE34: 否 | AF34: 2025-12-31 10:08:00 | AG34: 186****6788 | AH34: 蔡李任 | AI34: 2025-12-31 12:12:11 | AJ34: 150****7157‎‎‎‬‬‬ | AK34: 2026-01-01 09:00:03 | AL34: 7551083218 | AM34: 是
A35: SF5127722665550 | B35: 取宝-物流服务 | C35: WP25123088309157 | D35: 未导出 | E35: BAT251230202947 | F35: 已完成 | H35: 13178616287 | I35: 派送成功 | J35: 未打印 | K35: 2025-12-31 12:00 | L35: 邹*华 | M35: 186****6788‎‎‎‬‬‬ | N35: *******6788‎‎‎‬‬‬ | P35: 广东省东莞市东城街道东纵路东城段208号 东城万达中心写**********‎‎‎‬‬‬ | Q35: 邹*华 | R35: *******6788‎‎‎‬‬‬ | S35: 进店取立充充电宝的宝2个 | T35: 清溪宝家酒店二楼商务棋牌 | U35: 广东省东莞市清溪镇***************** *‎‎‎‬‬‬ | V35: 充电宝 | W35: 2 | X35: 1 | Z35: 寄付月结 | AA35: 顺丰特快 | AE35: 否 | AF35: 2025-12-30 17:25:46 | AG35: 186****6788 | AH35: 潘承寸 | AI35: 2025-12-30 21:36:26 | AJ35: 131****6287‎‎‎‬‬‬ | AK35: 2025-12-31 08:43:04 | AL35: 7551083218 | AM35: 是
A36: SF5106970421620 | B36: 取宝-物流服务 | C36: WP25123088304955 | D36: 未导出 | E36: BAT251230202501 | F36: 已完成 | H36: 13178616287 | I36: 派送成功 | J36: 未打印 | K36: 2025-12-31 12:00 | L36: 邹*华 | M36: 186****6788‎‎‎‬‬‬ | N36: *******6788‎‎‎‬‬‬ | P36: 广东省东莞市东城街道东纵路东城段208号 东城万达中心写**********‎‎‎‬‬‬ | Q36: 邹*华 | R36: *******6788‎‎‎‬‬‬ | S36: 进店取立充充电宝的宝2个 | T36: 清溪宝家酒店二楼商务棋牌 | U36: 广东省东莞市清溪镇***************** *‎‎‎‬‬‬ | V36: 充电宝 | W36: 2 | X36: 1 | Z36: 寄付月结 | AA36: 顺丰特快 | AE36: 否 | AF36: 2025-12-30 17:25:46 | AG36: 186****6788 | AH36: 潘承寸 | AI36: 2025-12-30 21:35:24 | AJ36: 131****6287‎‎‎‬‬‬ | AK36: 2025-12-31 08:43:04 | AL36: 7551083218 | AM36: 是 | AO36: 异常时间：2025-12-30 18:50:57； 异常类型：客户拒绝取证； 异常描述：客户收不到验证码； 审核意见：；
A37: SF5127722066632 | B37: 取宝-物流服务 | C37: WP25123088280271 | D37: 未导出 | E37: BAT251230199984 | F37: 异常结束 | H37: 17377165959 | I37: 派送成功 | J37: 未打印 | K37: 2025-12-31 12:00 | L37: 邹*华 | M37: 186****6788‎‎‎‬‬‬ | N37: *******6788‎‎‎‬‬‬ | P37: 广东省东莞市东城街道东纵路东城段208号 东城万达中心写**********‎‎‎‬‬‬ | Q37: 邹*华 | R37: *******6788‎‎‎‬‬‬ | S37: 进店取立充充电宝的宝2个 | T37: 塘厦惠影千都沐足 | U37: 广东省东莞市塘厦 镇*********‎‎‎‬‬‬ | V37: 充电宝 | W37: 1 | X37: 1 | Z37: 寄付月结 | AA37: 顺丰特快 | AE37: 否 | AF37: 2025-12-30 17:22:06 | AG37: 186****6788 | AH37: 李钊 | AI37: 2025-12-30 18:50:57 | AJ37: 173****5959‎‎‎‬‬‬ | AK37: 2025-12-31 11:08:26 | AL37: 7551083218 | AM37: 是 | AO37: 异常时间：2025-12-30 18:52:46； 异常类型：客户拒绝取证； 异常描述：客户收不到验证码； 审核意见：；
A38: SF5106970144442 | B38: 取宝-物流服务 | C38: WP25123088275704 | D38: 未导出 | E38: BAT251230199531 | F38: 异常结束 | H38: 17377165959 | I38: 派送成功 | J38: 未打印 | K38: 2025-12-31 12:00 | L38: 邹*华 | M38: 186****6788‎‎‎‬‬‬ | N38: *******6788‎‎‎‬‬‬ | P38: 广东省东莞市东城街道东纵路东城段208号 东城万达中心写**********‎‎‎‬‬‬ | Q38: 邹*华 | R38: *******6788‎‎‎‬‬‬ | S38: 进店取立充充电宝的宝2个 | T38: 塘厦惠影千都沐足 | U38: 广东省东莞市塘厦 镇*********‎‎‎‬‬‬ | V38: 充电宝 | W38: 2 | X38: 1 | Z38: 寄付月结 | AA38: 顺丰特快 | AE38: 否 | AF38: 2025-12-30 17:22:06 | AG38: 186****6788 | AH38: 李钊 | AI38: 2025-12-30 18:52:46 | AJ38: 173****5959‎‎‎‬‬‬ | AK38: 2025-12-31 11:08:26 | AL38: 7551083218 | AM38: 是
A39: SF5127702222006 | B39: 取宝-物流服务 | C39: WP25123087300735 | D39: 未导出 | E39: BAT251230099882 | F39: 已取消 | H39: 18681027015 | I39: 已取消 | J39: 未打印 | L39: 邹*华 | M39: 186****6788‎‎‎‬‬‬ | N39: *******6788‎‎‎‬‬‬ | P39: 广东省东莞市东城街道东纵路东城段208号 东城万达中心写**********‎‎‎‬‬‬ | Q39: 邹*华 | R39: *******6788‎‎‎‬‬‬ | S39: 进店取立充充电宝的宝2个 | T39: 清溪宝家酒店二楼商务棋牌 | U39: 广东省东莞市清溪镇***************** *‎‎‎‬‬‬ | V39: 充电宝 | W39: 2 | X39: 1 | Z39: 寄付月结 | AA39: 顺丰特快 | AE39: 否 | AF39: 2025-12-30 14:11:03 | AG39: 186****6788 | AH39: 唐伟华 | AJ39: 186****7015‎‎‎‬‬‬ | AL39: 7551083218 | AM39: 是
A40: SF5106901940142 | B40: 取宝-物流服务 | C40: WP25123087299207 | D40: 未导出 | E40: BAT251230099714 | F40: 已取消 | H40: 18681027015 | I40: 已取消 | J40: 未打印 | L40: 邹*华 | M40: 186****6788‎‎‎‬‬‬ | N40: *******6788‎‎‎‬‬‬ | P40: 广东省东莞市东城街道东纵路东城段208号 东城万达中心写**********‎‎‎‬‬‬ | Q40: 邹*华 | R40: *******6788‎‎‎‬‬‬ | S40: 进店取立充充电宝的宝2个 | T40: 清溪宝家酒店二楼商务棋牌 | U40: 广东省东莞市清溪镇***************** *‎‎‎‬‬‬ | V40: 充电宝 | W40: 2 | X40: 1 | Z40: 寄付月结 | AA40: 顺丰特快 | AE40: 否 | AF40: 2025-12-30 14:11:03 | AG40: 186****6788 | AL40: 7551083218 | AM40: 是
...

Sheet Sheet2
A1: 运单号 | B1: 任务类型 | C1: 收件手机 | G1: 运单号 | H1: 下单账号
A2: SF3268579296831 | B2: 补宝-物流服务 | C2: 155****0885‎‎‎‬‬‬ | G2: SF3268579296831 | H2: 155****0885
A3: SF3268579291750 | B3: 补宝-物流服务 | C3: 155****0885‎‎‎‬‬‬ | G3: SF3268579291750 | H3: 155****0885
A4: SF5127709690867 | B4: 补宝-物流服务 | C4: 155****0885‎‎‎‬‬‬ | G4: SF5127709690867 | H4: 155****0885
A5: SF5106905852824 | B5: 补宝-物流服务 | C5: 155****0885‎‎‎‬‬‬ | G5: SF5106905852824 | H5: 155****0885
A6: SF5105056503415 | B6: 补宝-物流服务 | C6: 181****7580‎‎‎‬‬‬ | G6: SF5105056503415 | H6: 134****6101
A7: SF5105056506251 | B7: 补宝-物流服务 | C7: 181****7580‎‎‎‬‬‬ | G7: SF5105056506251 | H7: 134****6101
A8: SF3266863453181 | B8: 补宝-物流服务 | C8: 181****7580‎‎‎‬‬‬ | G8: SF3266863453181 | H8: 134****6101
A9: SF3261464758524 | B9: 补宝-物流服务 | C9: 186****6788‎‎‎‬‬‬ | G9: SF3261464758524 | H9: 186****6788
A10: SF3261464758781 | B10: 补宝-物流服务 | C10: 186****6788‎‎‎‬‬‬ | G10: SF3261464758781 | H10: 186****6788
A11: SF3261417303446 | B11: 补宝-物流服务 | C11: 152****5518‎‎‎‬‬‬ | G11: SF3261417303446 | H11: 134****6101
A12: SF3261417303058 | B12: 补宝-物流服务 | C12: 152****5518‎‎‎‬‬‬ | G12: SF3261417303058 | H12: 134****6101
... A15: SF3260491849237 | B15: 补宝-物流服务 | C15: 158****0900‎‎‎‬‬‬ | G15: SF3260491849237 | H15: 134****6101
A16: SF3260420814593 | B16: 补宝-物流服务 | G16: SF3260420814593 | H16: 136****7868
A17: SF3260499115096 | B17: 补宝-物流服务 | C17: 186****8030‎‎‎‬‬‬ | G17: SF3260499115096 | H17: 134****6101
A18: SF3260499115906 | B18: 补宝-物流服务 | C18: 186****8030‎‎‎‬‬‬ | G18: SF3260499115906 | H18: 134****6101
A19: SF3278405753506 | B19: 补宝-物流服务 | C19: 186****6788‎‎‎‬‬‬ | G19: SF3278405753506 | H19: 186****6788
A20: SF3278434363447 | B20: 补宝-物流服务 | C20: 186****6788‎‎‎‬‬‬ | G20: SF3278434363447 | H20: 186****6788
A21: SF3278434363483 | B21: 补宝-物流服务 | C21: 186****6788‎‎‎‬‬‬ | G21: SF3278434363483 | H21: 186****6788
A22: SF3269834853653 | B22: 补宝-物流服务 | C22: 186****6788‎‎‎‬‬‬ | G22: SF3269834853653 | H22: 186****6788
A23: SF3269042397254 | B23: 补宝-物流服务 | C23: 181****6669‎‎‎‬‬‬ | G23: SF3269042397254 | H23: 130****4667
A24: SF3269933113650 | B24: 补宝-物流服务 | C24: 186****6788‎‎‎‬‬‬ | G24: SF3269933113650 | H24: 186****6788
A25: SF3278126546304 | B25: 补宝-物流服务 | C25: 186****6788‎‎‎‬‬‬ | G25: SF3278126546304 | H25: 186****6788
A26: SF3269248082701 | B26: 补宝-物流服务 | C26: 186****6788‎‎‎‬‬‬ | G26: SF3269248082701 | H26: 186****6788
A27: SF3269246608556 | B27: 补宝-物流服务 | C27: 186****6788‎‎‎‬‬‬ | G27: SF3269246608556 | H27: 186****6788
A28: SF3278179778744 | B28: 补宝-物流服务 | C28: 186****6788‎‎‎‬‬‬ | G28: SF3278179778744 | H28: 186****6788
... A173: SF5106905958549 | B173: 立充充电宝取机柜-仅物流 | C173: 155****0885‎‎‎‬‬‬ | G173: SF3266273769420 | H173: 131****2614
A174: SF3268277986250 | C174: 177****5688‎‎‎‬‬‬ | G174: SF3266238709946 | H174: 186****6788
A175: SF5106557446982 | C175: 177****5688‎‎‎‬‬‬ | G175: SF3261485880842 | H175: 186****6788
A176: SF5106557446946 | C176: 177****5688‎‎‎‬‬‬ | G176: SF3261485888202 | H176: 186****6788
A177: SF5105265169872 | C177: 155****0885‎‎‎‬‬‬ | G177: SF3261762960340 | H177: 131****2614
A178: SF3268714724220 | B178: 立充充电宝取机柜-物流服务 | C178: 186****6788‎‎‎‬‬‬ | G178: SF3261793913657 | H178: 186****6788
A179: SF5127722204781,SF2074509697134 | B179: 立充充电宝取机柜-物流服务 | C179: 186****6788‎‎‎‬‬‬ | G179: SF3268270973716 | H179: 131****2614
A180: SF5106979506489 | B180: 立充充电宝取机柜-物流服务 | C180: 186****6788‎‎‎‬‬‬ | G180: SF3261642298877 | H180: 186****6788
A181: SF5106970083922 | B181: 立充充电宝取机柜-物流服务 | C181: 186****6788‎‎‎‬‬‬ | G181: SF3260956999481 | H181: 136****7868
A182: SF3268545240764 | B182: 立充充电宝取机柜-物流服务 | C182: 155****0885‎‎‎‬‬‬ | G182: SF3269495090258 | H182: 134****9085
A183: SF5106997533365 | B183: 立充充电宝取机柜-物流服务 | C183: 155****0885‎‎‎‬‬‬ | G183: SF3269768176117 | H183: 131****2614
A184: SF5127766316133 | B184: 立充充电宝取机柜-物流服务 | C184: 155****0885‎‎‎‬‬‬ | G184: SF3269768176320 | H184: 131****2614
A185: SF3268571425528 | B185: 立充充电宝取机柜-物流服务 | C185: 186****6788‎‎‎‬‬‬ | G185: SF3269707179242 | H185: 131****2614
A186: SF5106901786306 | B186: 立充充电宝取机柜-物流服务 | C186: 186****6788‎‎‎‬‬‬ | G186: SF3278720614683 | H186: 186****6788
...

Sheet Sheet3
J1: 手机号 | K1: 账号所属公司 | L1: 公司性质
J2: 165****7666 | K2: 深圳市锐丰伟业科技有限公司 | L2: 服务商
J3: 186****8003 | K3: 河北亘石信息科技有限公司 | L3: 服务商
J4: 155****0885 | K4: 大连浩源满航空服务有限公司 | L4: 服务商
J5: 134****6101 | K5: 成都江源易通信息技术有限公司 | L5: 服务商
J6: 156****1234 | K6: 内蒙古悦盈科技有限公司 | L6: 服务商
J7: 137****1781 | K7: 东莞市聚伴科技有限公司 | L7: 服务商
J8: 181****5776 | K8: 福建无现新生信息科技有限公司 | L8: 服务商
J9: 136****7868 | K9: 山东省点线面网络科技有限公司 | L9: 服务商
J10: 131****2614 | K10: 辽宁深蓝数据服务有限公司 | L10: 服务商
J11: 158****6590 | K11: 江西森楠科技有限公司 | L11: 服务商
J12: 187****4440 | K12: 长治市聚英科技有限公司 | L12: 服务商
... J17: 134****9085 | K17: 深圳市嘉嘉电科技有限公司 | L17: 服务商

Sheet Sheet5
A1: 快递运单费用
A2: 序号 | B2: 日期 | C2: 运单号码 | D2: 寄件地区 | E2: 到件地区 | F2: 对方公司名称 | G2: 计费重量 | H2: 产品类型 | I2: 付款方式 | J2: 费用(元) | K2: 折扣/促销 | L2: 应付金额 | M2: 经手人 | N2: 服务 | O2: 任务类型 | P2: 下单账号 | Q2: 账号所属公司 | R2: 公司性质 | S2: 备注
A3: 1 | B3: 12-01 | C3: SF3262372117661 | D3: 雅安 | E3: 成都/资阳/眉山 | F3: 文刚 | G3: 1.000 | H3: 顺丰标快 | I3: 寄转第三方 | J3: 13.00 | K3: 0.00 | L3: 13.00 | M3: 文刚 | N3: 运费 | O3: 取宝-物流服务 | P3: 184****1003‎‎‎‬‬‬
A4: 2 | B4: 12-01 | C4: SF3262372117661 | D4: 雅安 | E4: 成都/资阳/眉山 | F4: 文刚 | G4: 0.000 | H4: 顺丰标快 | I4: 寄转第三方 | J4: 2.00 | K4: 0.00 | L4: 2.00 | M4: 文刚 | N4: 包装服务 | O4: 取宝-物流服务 | P4: 184****1003‎‎‎‬‬‬
A5: 3 | B5: 12-01 | C5: SF3262372954357 | D5: 雅安 | E5: 成都/资阳/眉山 | F5: 文刚 | G5: 4.500 | H5: 顺丰标快 | I5: 寄转第三方 | J5: 20.00 | K5: 0.00 | L5: 20.00 | M5: 文刚 | N5: 运费 | O5: 立充充电宝取机柜-物流服务 | P5: 184****1003‎‎‎‬‬‬
A6: 4 | B6: 12-01 | C6: SF3262372954357 | D6: 雅安 | E6: 成都/资阳/眉山 | F6: 文刚 | G6: 0.000 | H6: 顺丰标快 | I6: 寄转第三方 | J6: 7.00 | K6: 0.00 | L6: 7.00 | M6: 文刚 | N6: 包装服务 | O6: 立充充电宝取机柜-物流服务 | P6: 184****1003‎‎‎‬‬‬
A7: 5 | B7: 12-01 | C7: SF3262377404072 | D7: 东莞 | E7: 东莞 | F7: 邹小华 | G7: 1.000 | H7: 顺丰标快 | I7: 寄转第三方 | J7: 11.00 | K7: 0.00 | L7: 11.00 | M7: 邹小华 | N7: 运费 | O7: 取宝-物流服务 | P7: 186****6788‎‎‎‬‬‬ | Q7: 东莞市中汇信息技术有限公司
A8: 6 | B8: 12-01 | C8: SF3262377404072 | D8: 东莞 | E8: 东莞 | F8: 邹小华 | G8: 0.000 | H8: 顺丰标快 | I8: 寄转第三方 | J8: 2.00 | K8: 0.00 | L8: 2.00 | M8: 邹小华 | N8: 包装服务 | O8: 取宝-物流服务 | P8: 186****6788‎‎‎‬‬‬ | Q8: 东莞市中汇信息技术有限公司
A9: 7 | B9: 12-01 | C9: SF3262378607753 | D9: 东莞 | E9: 东莞 | F9: 邹小华 | G9: 1.000 | H9: 顺丰标快 | I9: 寄转第三方 | J9: 11.00 | K9: 0.00 | L9: 11.00 | M9: 邹小华 | N9: 运费 | O9: 取宝-物流服务 | P9: 186****6788‎‎‎‬‬‬ | Q9: 东莞市中汇信息技术有限公司
A10: 8 | B10: 12-01 | C10: SF3295326848005 | D10: 东莞 | E10: 东莞 | F10: 邹小华 | G10: 1.000 | H10: 顺丰标快 | I10: 寄转第三方 | J10: 11.00 | K10: 0.00 | L10: 11.00 | M10: 邹小华 | N10: 运费 | O10: 取宝-物流服务 | P10: 186****6788‎‎‎‬‬‬ | Q10: 东莞市中汇信息技术有限公司
A11: 9 | B11: 12-01 | C11: SF3295326848005 | D11: 东莞 | E11: 东莞 | F11: 邹小华 | G11: 0.000 | H11: 顺丰标快 | I11: 寄转第三方 | J11: 1.00 | K11: 0.00 | L11: 1.00 | M11: 邹小华 | N11: 包装服务 | O11: 取宝-物流服务 | P11: 186****6788‎‎‎‬‬‬ | Q11: 东莞市中汇信息技术有限公司
A12: 10 | B12: 12-01 | C12: SF3295364078732 | D12: 雅安 | E12: 成都/资阳/眉山 | F12: 文刚 | G12: 1.000 | H12: 顺丰标快 | I12: 寄转第三方 | J12: 13.00 | K12: 0.00 | L12: 13.00 | M12: 文刚 | N12: 运费 | O12: 取宝-物流服务 | P12: 184****1003‎‎‎‬‬‬
A13: 11 | B13: 12-01 | C13: SF3295364078732 | D13: 雅安 | E13: 成都/资阳/眉山 | F13: 文刚 | G13: 0.000 | H13: 顺丰标快 | I13: 寄转第三方 | J13: 2.00 | K13: 0.00 | L13: 2.00 | M13: 文刚 | N13: 包装服务 | O13: 取宝-物流服务 | P13: 184****1003‎‎‎‬‬‬
A14: 12 | B14: 12-01 | C14: SF3295364078769 | D14: 雅安 | E14: 成都/资阳/眉山 | F14: 文刚 | G14: 1.000 | H14: 顺丰标快 | I14: 寄转第三方 | J14: 13.00 | K14: 0.00 | L14: 13.00 | M14: 文刚 | N14: 运费 | O14: 取宝-物流服务 | P14: 184****1003‎‎‎‬‬‬
A15: 13 | B15: 12-01 | C15: SF3295364078769 | D15: 雅安 | E15: 成都/资阳/眉山 | F15: 文刚 | G15: 0.000 | H15: 顺丰标快 | I15: 寄转第三方 | J15: 2.00 | K15: 0.00 | L15: 2.00 | M15: 文刚 | N15: 包装服务 | O15: 取宝-物流服务 | P15: 184****1003‎‎‎‬‬‬
A16: 14 | B16: 12-01 | C16: SF3295365022962 | D16: 东莞 | E16: 东莞 | F16: 邹小华 | G16: 2.500 | H16: 顺丰标快 | I16: 寄转第三方 | J16: 13.00 | K16: 0.00 | L16: 13.00 | M16: 邹小华 | N16: 运费 | O16: 立充充电宝取机柜-物流服务 | P16: 186****6788‎‎‎‬‬‬ | Q16: 东莞市中汇信息技术有限公司
A17: 15 | B17: 12-01 | C17: SF3295365941133 | D17: 东莞 | E17: 东莞 | F17: 邹小华 | G17: 1.000 | H17: 顺丰标快 | I17: 寄转第三方 | J17: 11.00 | K17: 0.00 | L17: 11.00 | M17: 邹小华 | N17: 运费 | O17: 取宝-物流服务 | P17: 186****6788‎‎‎‬‬‬ | Q17: 东莞市中汇信息技术有限公司
A18: 16 | B18: 12-02 | C18: SF3262372117661 | D18: 雅安 | E18: 成都/资阳/眉山 | F18: 文刚 | G18: 0.000 | H18: 顺丰标快 | I18: 寄付 | J18: 6.00 | K18: 0.00 | L18: 6.00 | M18: 文刚 | N18: 收件微派 | O18: 取宝-物流服务 | P18: 184****1003‎‎‎‬‬‬
A19: 17 | B19: 12-02 | C19: SF3262377404072 | D19: 东莞 | E19: 东莞 | F19: 邹小华 | G19: 0.000 | H19: 顺丰标快 | I19: 寄付 | J19: 6.00 | K19: 0.00 | L19: 6.00 | M19: 邹小华 | N19: 收件微派 | O19: 取宝-物流服务 | P19: 186****6788‎‎‎‬‬‬ | Q19: 东莞市中汇信息技术有限公司
A20: 18 | B20: 12-02 | C20: SF3262378607753 | D20: 东莞 | E20: 东莞 | F20: 邹小华 | G20: 0.000 | H20: 顺丰标快 | I20: 寄付 | J20: 6.00 | K20: 0.00 | L20: 6.00 | M20: 邹小华 | N20: 收件微派 | O20: 取宝-物流服务 | P20: 186****6788‎‎‎‬‬‬ | Q20: 东莞市中汇信息技术有限公司
A21: 19 | B21: 12-02 | C21: SF3262992584639 | D21: 深圳 | E21: 东莞 | F21: 广东久益智付科技有限公司 | G21: 1.000 | H21: 顺丰标快 | I21: 寄转第三方 | J21: 13.00 | K21: 0.00 | L21: 13.00 | M21: 吴广继 | N21: 运费 | O21: 取宝-仅物流 | P21: 130****4667‎‎‎‬‬‬ | Q21: 广东久益智付科技有限公司
A22: 20 | B22: 12-02 | C22: SF3295326848005 | D22: 东莞 | E22: 东莞 | F22: 邹小华 | G22: 0.000 | H22: 顺丰标快 | I22: 寄付 | J22: 6.00 | K22: 0.00 | L22: 6.00 | M22: 邹小华 | N22: 收件微派 | O22: 取宝-物流服务 | P22: 186****6788‎‎‎‬‬‬ | Q22: 东莞市中汇信息技术有限公司
A23: 21 | B23: 12-02 | C23: SF3295364078732 | D23: 雅安 | E23: 成都/资阳/眉山 | F23: 文刚 | G23: 0.000 | H23: 顺丰标快 | I23: 寄付 | J23: 6.00 | K23: 0.00 | L23: 6.00 | M23: 文刚 | N23: 收件微派 | O23: 取宝-物流服务 | P23: 184****1003‎‎‎‬‬‬
A24: 22 | B24: 12-02 | C24: SF3295364078769 | D24: 雅安 | E24: 成都/资阳/眉山 | F24: 文刚 | G24: 0.000 | H24: 顺丰标快 | I24: 寄付 | J24: 6.00 | K24: 0.00 | L24: 6.00 | M24: 文刚 | N24: 收件微派 | O24: 取宝-物流服务 | P24: 184****1003‎‎‎‬‬‬
A25: 23 | B25: 12-02 | C25: SF3295365022962 | D25: 东莞 | E25: 东莞 | F25: 邹小华 | G25: 0.000 | H25: 顺丰标快 | I25: 寄付 | J25: 3.00 | K25: 0.00 | L25: 3.00 | M25: 邹小华 | N25: 收件微派 | O25: 立充充电宝取机柜-物流服务 | P25: 186****6788‎‎‎‬‬‬ | Q25: 东莞市中汇信息技术有限公司
A26: 24 | B26: 12-02 | C26: SF3295365941133 | D26: 东莞 | E26: 东莞 | F26: 邹小华 | G26: 0.000 | H26: 顺丰标快 | I26: 寄付 | J26: 6.00 | K26: 0.00 | L26: 6.00 | M26: 邹小华 | N26: 收件微派 | O26: 取宝-物流服务 | P26: 186****6788‎‎‎‬‬‬ | Q26: 东莞市中汇信息技术有限公司
A27: 25 | B27: 12-03 | C27: SF3262004095424 | D27: 深圳 | E27: 东莞 | F27: 吴珊珊 | G27: 1.000 | H27: 顺丰标快 | I27: 寄转第三方 | J27: 13.00 | K27: 0.00 | L27: 13.00 | M27: 饶云普 | N27: 运费 | O27: 立充充电宝取机柜-仅服务 | P27: 177****5688‎‎‎‬‬‬
A28: 26 | B28: 12-03 | C28: SF3262004095424 | D28: 深圳 | E28: 东莞 | F28: 吴珊珊 | G28: 0.000 | H28: 顺丰标快 | I28: 寄转第三方 | J28: 1.00 | K28: 0.00 | L28: 1.00 | M28: 饶云普 | N28: 包装服务 | O28: 立充充电宝取机柜-仅服务 | P28: 177****5688‎‎‎‬‬‬
A29: 27 | B29: 12-03 | C29: SF3262004095497 | D29: 深圳 | E29: 东莞 | F29: 吴珊珊 | G29: 2.300 | H29: 顺丰标快 | I29: 寄转第三方 | J29: 16.00 | K29: 0.00 | L29: 16.00 | M29: 饶云普 | N29: 运费 | O29: 立充充电宝取机柜-仅服务 | P29: 177****5688‎‎‎‬‬‬
A30: 28 | B30: 12-03 | C30: SF3262004095497 | D30: 深圳 | E30: 东莞 | F30: 吴珊珊 | G30: 0.000 | H30: 顺丰标快 | I30: 寄转第三方 | J30: 4.00 | K30: 0.00 | L30: 4.00 | M30: 饶云普 | N30: 包装服务 | O30: 立充充电宝取机柜-仅服务 | P30: 177****5688‎‎‎‬‬‬
A31: 29 | B31: 12-03 | C31: SF3262004095742 | D31: 深圳 | E31: 东莞 | F31: 吴珊珊 | G31: 1.000 | H31: 顺丰标快 | I31: 寄转第三方 | J31: 13.00 | K31: 0.00 | L31: 13.00 | M31: 饶云普 | N31: 运费 | O31: 立充充电宝取机柜-仅服务 | P31: 177****5688‎‎‎‬‬‬
A32: 30 | B32: 12-03 | C32: SF3262004095742 | D32: 深圳 | E32: 东莞 | F32: 吴珊珊 | G32: 0.000 | H32: 顺丰标快 | I32: 寄转第三方 | J32: 1.00 | K32: 0.00 | L32: 1.00 | M32: 饶云普 | N32: 包装服务 | O32: 立充充电宝取机柜-仅服务 | P32: 177****5688‎‎‎‬‬‬
A33: 31 | B33: 12-03 | C33: SF3262004097071 | D33: 深圳 | E33: 东莞 | F33: 吴珊珊 | G33: 1.000 | H33: 顺丰标快 | I33: 寄转第三方 | J33: 13.00 | K33: 0.00 | L33: 13.00 | M33: 饶云普 | N33: 运费 | O33: 立充充电宝取机柜-仅服务 | P33: 177****5688‎‎‎‬‬‬
A34: 32 | B34: 12-03 | C34: SF3262004097071 | D34: 深圳 | E34: 东莞 | F34: 吴珊珊 | G34: 0.000 | H34: 顺丰标快 | I34: 寄转第三方 | J34: 1.00 | K34: 0.00 | L34: 1.00 | M34: 饶云普 | N34: 包装服务 | O34: 立充充电宝取机柜-仅服务 | P34: 177****5688‎‎‎‬‬‬
A35: 33 | B35: 12-03 | C35: SF3262016306209 | D35: 东莞 | E35: 东莞 | F35: 邹小华 | G35: 1.000 | H35: 顺丰标快 | I35: 寄转第三方 | J35: 11.00 | K35: 0.00 | L35: 11.00 | M35: 邹小华 | N35: 运费 | O35: 取宝-物流服务 | P35: 186****6788‎‎‎‬‬‬ | Q35: 东莞市中汇信息技术有限公司
A36: 34 | B36: 12-03 | C36: SF3262016306209 | D36: 东莞 | E36: 东莞 | F36: 邹小华 | G36: 0.000 | H36: 顺丰标快 | I36: 寄转第三方 | J36: 1.00 | K36: 0.00 | L36: 1.00 | M36: 邹小华 | N36: 包装服务 | O36: 取宝-物流服务 | P36: 186****6788‎‎‎‬‬‬ | Q36: 东莞市中汇信息技术有限公司
A37: 35 | B37: 12-03 | C37: SF3262016306218 | D37: 东莞 | E37: 东莞 | F37: 邹小华 | G37: 1.000 | H37: 顺丰标快 | I37: 寄转第三方 | J37: 11.00 | K37: 0.00 | L37: 11.00 | M37: 邹小华 | N37: 运费 | O37: 取宝-物流服务 | P37: 186****6788‎‎‎‬‬‬ | Q37: 东莞市中汇信息技术有限公司
A38: 36 | B38: 12-03 | C38: SF3262016306218 | D38: 东莞 | E38: 东莞 | F38: 邹小华 | G38: 0.000 | H38: 顺丰标快 | I38: 寄转第三方 | J38: 1.00 | K38: 0.00 | L38: 1.00 | M38: 邹小华 | N38: 包装服务 | O38: 取宝-物流服务 | P38: 186****6788‎‎‎‬‬‬ | Q38: 东莞市中汇信息技术有限公司
A39: 37 | B39: 12-03 | C39: SF3262025177518 | D39: 东莞 | E39: 东莞 | F39: 邹小华 | G39: 2.400 | H39: 顺丰标快 | I39: 寄转第三方 | J39: 12.00 | K39: 0.00 | L39: 12.00 | M39: 邹小华 | N39: 运费 | O39: 立充充电宝取机柜-物流服务 | P39: 186****6788‎‎‎‬‬‬ | Q39: 东莞市中汇信息技术有限公司
A40: 38 | B40: 12-03 | C40: SF3262025177518 | D40: 东莞 | E40: 东莞 | F40: 邹小华 | G40: 0.000 | H40: 顺丰标快 | I40: 寄转第三方 | J40: 4.00 | K40: 0.00 | L40: 4.00 | M40: 邹小华 | N40: 包装服务 | O40: 立充充电宝取机柜-物流服务 | P40: 186****6788‎‎‎‬‬‬ | Q40: 东莞市中汇信息技术有限公司
...
